Workbook

Sheet Реестр рисков
A1: Наименование проекта: TableMind — AI-сервис проверки Excel-моделей (веб-аудит + надстройка Excel)
A2: Методы идентификации: анализ документации (SDD, бизнес-анализ, WBS), контрольные листы (Боэм, ДеМарко — Листер), анализ допущений ПЗ1, мозговой штурм команды. Жёлтые ячейки — экспертные оценки; остальное считается формулами.
A4: № | B4: Обозна- чение | C4: Наименование риска | D4: Категория | E4: Влияние на проект (последствия) | F4: Триггер | G4: Вероят- ность P (0–1) | H4: Воздей- ствие I (0–1) | I4: Коэфф. K = P×I | J4: Приоритет | K4: Метод реагирования | L4: Меры реагирования | M4: Ответственный | N4: Работы WBS | O4: Потери при наступлении, BYN | P4: Ожидаемые потери P×потери, BYN | Q4: Затраты на меры, BYN | R4: Целесообразность мер | S4: P после мер | T4: I после мер | U4: Остаточный K | V4: Остаточный приоритет | W4: Ранг по K
A5: 1 | B5: ="R"&A5 -> R1 | C5: Крупные платформы (Microsoft Copilot, ChatGPT / Claude for Excel) выпустят бесплатный «режим проверки» | D5: Рыночный | E5: Потеря уникальности, падение конверсии и выручки | F5: Анонс функции аудита или верификации у лидеров рынка | G5: 0.7 | H5: 0.8 | I5: =G5*H5 -> 0.56 | J5: =IF(I5>'Шкалы оценки'!$B$21,"Высокий",IF(I5>='Шкалы оценки'!$B$22,"Средний","Низкий")) -> Высокий | K5: Снижение | L5: Фокус на нише аудита финмоделей; сверка текста с таблицей и provenance; API/MCP как слой проверки для чужих AI-агентов; ежемесячный мониторинг конкурентов | M5: Владелец продукта | N5: 1.0, 15.0 | O5: 45000 | P5: =G5*O5 -> 31500 | Q5: 5000 | R5: =IF(K5="Принятие","Принятие: покрывается резервом",IF(Q5<P5,"Оправданы (затраты < ожид. потерь)","Пересмотреть меры")) -> Оправданы (затраты < ожид. потерь) | S5: 0.5 | T5: 0.6 | U5: =S5*T5 -> 0.3 | V5: =IF(U5>'Шкалы оценки'!$B$21,"Высокий",IF(U5>='Шкалы оценки'!$B$22,"Средний","Низкий")) -> Средний | W5: =RANK(I5,$I$5:$I$23)+COUNTIF($I$5:I5,I5)-1 -> 2
A6: 2 | B6: ="R"&A6 -> R2 | C6: Высокая доля ложных срабатываний правил (precision критичных находок < 90%) | D6: Технический | E6: Потеря доверия, отток бета-пользователей, провал критерия приёмки | F6: Доля подавленных находок > 15%; precision ниже порога в CI | G6: 0.6 | H6: 0.9 | I6: =G6*H6 -> 0.54 | J6: =IF(I6>'Шкалы оценки'!$B$21,"Высокий",IF(I6>='Шкалы оценки'!$B$22,"Средний","Низкий")) -> Высокий | K6: Снижение | L6: Precision — главная метрика; чистый eval-набор; уровни серьёзности; подавление правил; правило выпускается только после прохождения eval | M6: ML/LLM-инженер | N6: 5.0, 6.0 | O6: 70000 | P6: =G6*O6 -> 42000 | Q6: 8000 | R6: =IF(K6="Принятие","Принятие: покрывается резервом",IF(Q6<P6,"Оправданы (затраты < ожид. потерь)","Пересмотреть меры")) -> Оправданы (затраты < ожид. потерь) | S6: 0.3 | T6: 0.6 | U6: =S6*T6 -> 0.18 | V6: =IF(U6>'Шкалы оценки'!$B$21,"Высокий",IF(U6>='Шкалы оценки'!$B$22,"Средний","Низкий")) -> Средний | W6: =RANK(I6,$I$5:$I$23)+COUNTIF($I$5:I6,I6)-1 -> 4
A7: 3 | B7: ="R"&A7 -> R3 | C7: Пользователи не захотят менять привычную работу в Excel и пробовать новый сервис | D7: Рыночный | E7: Нет активации и продаж — продукт не подтверждает ценность | F7: Менее 8% посетителей начинают аудит; нет повторных аудитов | G7: 0.7 | H7: 0.9 | I7: =G7*H7 -> 0.63 | J7: =IF(I7>'Шкалы оценки'!$B$21,"Высокий",IF(I7>='Шкалы оценки'!$B$22,"Средний","Низкий")) -> Высокий | K7: Снижение | L7: Старт с веб-аудита без установки и надстройки внутри Excel; собственный редактор — только после подтверждения спроса; бесплатный тизер находок | M7: Владелец продукта | N7: 4.0, 12.0 | O7: 70000 | P7: =G7*O7 -> 49000 | Q7: 4000 | R7: =IF(K7="Принятие","Принятие: покрывается резервом",IF(Q7<P7,"Оправданы (затраты < ожид. потерь)","Пересмотреть меры")) -> Оправданы (затраты < ожид. потерь) | S7: 0.4 | T7: 0.6 | U7: =S7*T7 -> 0.24 | V7: =IF(U7>'Шкалы оценки'!$B$21,"Высокий",IF(U7>='Шкалы оценки'!$B$22,"Средний","Низкий")) -> Средний | W7: =RANK(I7,$I$5:$I$23)+COUNTIF($I$5:I7,I7)-1 -> 1
A8: 4 | B8: ="R"&A8 -> R4 | C8: Срыв сроков критического пути из-за недооценки трудоёмкости (ядро, надстройка) | D8: Организационный | E8: Сдвиг релиза, рост затрат на оплату труда | F8: Отставание > 2 недель от базового плана на воротах | G8: 0.8 | H8: 0.7 | I8: =G8*H8 -> 0.56 | J8: =IF(I8>'Шкалы оценки'!$B$21,"Высокий",IF(I8>='Шкалы оценки'!$B$22,"Средний","Низкий")) -> Высокий | K8: Снижение | L8: Ворота фаз, еженедельный контроль по диаграмме Ганта, MoSCoW — перенос Should в v2, AI-агенты для типового кода | M8: Руководитель проекта | N8: 6.0, 12.0 | O8: 40000 | P8: =G8*O8 -> 32000 | Q8: 3000 | R8: =IF(K8="Принятие","Принятие: покрывается резервом",IF(Q8<P8,"Оправданы (затраты < ожид. потерь)","Пересмотреть меры")) -> Оправданы (затраты < ожид. потерь) | S8: 0.4 | T8: 0.5 | U8: =S8*T8 -> 0.2 | V8: =IF(U8>'Шкалы оценки'!$B$21,"Высокий",IF(U8>='Шкалы оценки'!$B$22,"Средний","Низкий")) -> Средний | W8: =RANK(I8,$I$5:$I$23)+COUNTIF($I$5:I8,I8)-1 -> 3
A9: 5 | B9: ="R"&A9 -> R5 | C9: Пользователи не готовы загружать конфиденциальные финмодели в облако | D9: Рыночный | E9: Низкая активация, мало данных для проверки ценности | F9: Отказы на шаге загрузки > 70% | G9: 0.5 | H9: 0.8 | I9: =G9*H9 -> 0.4 | J9: =IF(I9>'Шкалы оценки'!$B$21,"Высокий",IF(I9>='Шкалы оценки'!$B$22,"Средний","Низкий")) -> Средний | K9: Снижение | L9: Блок доверия у загрузчика, хостинг в ЕС, удаление файлов по сроку, отказ от обучения на данных, демо-файл «проверить на примере» | M9: Руководитель проекта | N9: 2.0, 8.0 | O9: 35000 | P9: =G9*O9 -> 17500 | Q9: 3000 | R9: =IF(K9="Принятие","Принятие: покрывается резервом",IF(Q9<P9,"Оправданы (затраты < ожид. потерь)","Пересмотреть меры")) -> Оправданы (затраты < ожид. потерь) | S9: 0.3 | T9: 0.7 | U9: =S9*T9 -> 0.21 | V9: =IF(U9>'Шкалы оценки'!$B$21,"Высокий",IF(U9>='Шкалы оценки'!$B$22,"Средний","Низкий")) -> Средний | W9: =RANK(I9,$I$5:$I$23)+COUNTIF($I$5:I9,I9)-1 -> 5
A10: 6 | B10: ="R"&A10 -> R6 | C10: Сложные элементы xlsx (объединённые ячейки, массивы, локали, внешние ссылки) — расхождение пересчёта с Excel | D10: Технический | E10: Ошибочные находки, сдвиг сроков разработки ядра | F10: Доля ошибок парсинга > 5% на eval-наборе | G10: 0.6 | H10: 0.6 | I10: =G10*H10 -> 0.36 | J10: =IF(I10>'Шкалы оценки'!$B$21,"Высокий",IF(I10>='Шкалы оценки'!$B$22,"Средний","Низкий")) -> Средний | K10: Снижение | L10: Набор эталонных книг; сложные элементы только читаются с предупреждением и пометкой «проверено частично» | M10: Бэкенд-разработчик 2 | N10: 6.0 | O10: 20000 | P10: =G10*O10 -> 12000 | Q10: 4000 | R10: =IF(K10="Принятие","Принятие: покрывается резервом",IF(Q10<P10,"Оправданы (затраты < ожид. потерь)","Пересмотреть меры")) -> Оправданы (затраты < ожид. потерь) | S10: 0.4 | T10: 0.4 | U10: =S10*T10 -> 0.16 | V10: =IF(U10>'Шкалы оценки'!$B$21,"Высокий",IF(U10>='Шкалы оценки'!$B$22,"Средний","Низкий")) -> Средний | W10: =RANK(I10,$I$5:$I$23)+COUNTIF($I$5:I10,I10)-1 -> 6
A11: 7 | B11: ="R"&A11 -> R7 | C11: Уход или выгорание ключевого разработчика ядра верификации | D11: Организационный | E11: Потеря знаний, срыв сроков критического пути | F11: Снижение вовлечённости, переработки, внешнее предложение о работе | G11: 0.4 | H11: 0.8 | I11: =G11*H11 -> 0.32 | J11: =IF(I11>'Шкалы оценки'!$B$21,"Высокий",IF(I11>='Шкалы оценки'!$B$22,"Средний","Низкий")) -> Средний | K11: Снижение | L11: ADR и документация, обязательное код-ревью, совместное владение ядром двумя разработчиками, контроль нагрузки | M11: Руководитель проекта | N11: 6.0, 12.0 | O11: 30000 | P11: =G11*O11 -> 12000 | Q11: 5000 | R11: =IF(K11="Принятие","Принятие: покрывается резервом",IF(Q11<P11,"Оправданы (затраты < ожид. потерь)","Пересмотреть меры")) -> Оправданы (затраты < ожид. потерь) | S11: 0.2 | T11: 0.5 | U11: =S11*T11 -> 0.1 | V11: =IF(U11>'Шкалы оценки'!$B$21,"Высокий",IF(U11>='Шкалы оценки'!$B$22,"Средний","Низкий")) -> Низкий | W11: =RANK(I11,$I$5:$I$23)+COUNTIF($I$5:I11,I11)-1 -> 8
A12: 8 | B12: ="R"&A12 -> R8 | C12: Рост цен или изменение условий LLM API | D12: Финансовый | E12: Снижение валовой маржи ниже 65% | F12: Стоимость LLM > 30% выручки на пользователя | G12: 0.5 | H12: 0.6 | I12: =G12*H12 -> 0.3 | J12: =IF(I12>'Шкалы оценки'!$B$21,"Высокий",IF(I12>='Шкалы оценки'!$B$22,"Средний","Низкий")) -> Средний | K12: Снижение | L12: LLM gateway с несколькими провайдерами, кэш промптов, эвристики до вызова LLM, лимиты тарифов | M12: ML/LLM-инженер | N12: 10.0 | O12: 15000 | P12: =G12*O12 -> 7500 | Q12: 3000 | R12: =IF(K12="Принятие","Принятие: покрывается резервом",IF(Q12<P12,"Оправданы (затраты < ожид. потерь)","Пересмотреть меры")) -> Оправданы (затраты < ожид. потерь) | S12: 0.4 | T12: 0.4 | U12: =S12*T12 -> 0.16 | V12: =IF(U12>'Шкалы оценки'!$B$21,"Высокий",IF(U12>='Шкалы оценки'!$B$22,"Средний","Низкий")) -> Средний | W12: =RANK(I12,$I$5:$I$23)+COUNTIF($I$5:I12,I12)-1 -> 9
A13: 9 | B13: ="R"&A13 -> R9 | C13: Низкая конверсия Free → платный тариф (< 2%) | D13: Финансовый | E13: Цель «≥ 50 платящих пользователей» не достигнута | F13: Конверсия < 2% через месяц после запуска оплаты | G13: 0.5 | H13: 0.7 | I13: =G13*H13 -> 0.35 | J13: =IF(I13>'Шкалы оценки'!$B$21,"Высокий",IF(I13>='Шкалы оценки'!$B$22,"Средний","Низкий")) -> Средний | K13: Снижение | L13: Оплата в точке максимальной ценности («исправить и скачать»), разовый аудит 9 €, пробный Pro 7 дней, A/B-тест цен | M13: Владелец продукта | N13: 11.0, 15.0 | O13: 30000 | P13: =G13*O13 -> 15000 | Q13: 3000 | R13: =IF(K13="Принятие","Принятие: покрывается резервом",IF(Q13<P13,"Оправданы (затраты < ожид. потерь)","Пересмотреть меры")) -> Оправданы (затраты < ожид. потерь) | S13: 0.3 | T13: 0.5 | U13: =S13*T13 -> 0.15 | V13: =IF(U13>'Шкалы оценки'!$B$21,"Высокий",IF(U13>='Шкалы оценки'!$B$22,"Средний","Низкий")) -> Средний | W13: =RANK(I13,$I$5:$I$23)+COUNTIF($I$5:I13,I13)-1 -> 7
A14: 10 | B14: ="R"&A14 -> R10 | C14: Превышение бюджета проекта | D14: Финансовый | E14: Нехватка средств на запуск и маркетинг | F14: Освоение бюджета опережает план более чем на 10% | G14: 0.4 | H14: 0.6 | I14: =G14*H14 -> 0.24 | J14: =IF(I14>'Шкалы оценки'!$B$21,"Высокий",IF(I14>='Шкалы оценки'!$B$22,"Средний","Низкий")) -> Средний | K14: Принятие | L14: Резерв 10% от базовой стоимости (47 000 BYN), ежемесячный контроль затрат, приоритизация Must have | M14: Руководитель проекта | N14: все | O14: 25000 | P14: =G14*O14 -> 10000 | Q14: 500 | R14: =IF(K14="Принятие","Принятие: покрывается резервом",IF(Q14<P14,"Оправданы (затраты < ожид. потерь)","Пересмотреть меры")) -> Принятие: покрывается резервом | S14: 0.5 | T14: 0.4 | U14: =S14*T14 -> 0.2 | V14: =IF(U14>'Шкалы оценки'!$B$21,"Высокий",IF(U14>='Шкалы оценки'!$B$22,"Средний","Низкий")) -> Средний | W14: =RANK(I14,$I$5:$I$23)+COUNTIF($I$5:I14,I14)-1 -> 13
A15: 11 | B15: ="R"&A15 -> R11 | C15: Лицензия движка пересчёта формул (например, GPLv3) несовместима с закрытым SaaS | D15: Правовой | E15: Замена библиотеки, +1–2 месяца на критическом пути | F15: Выбрана библиотека с copyleft-лицензией | G15: 0.4 | H15: 0.7 | I15: =G15*H15 -> 0.28 | J15: =IF(I15>'Шкалы оценки'!$B$21,"Высокий",IF(I15>='Шкалы оценки'!$B$22,"Средний","Низкий")) -> Средний | K15: Уклонение | L15: Проверка лицензий на этапе архитектуры, выбор permissive-библиотек или собственный пересчёт, проверка лицензий в CI | M15: Бэкенд-разработчик 1 | N15: 3.0, 6.0 | O15: 30000 | P15: =G15*O15 -> 12000 | Q15: 2000 | R15: =IF(K15="Принятие","Принятие: покрывается резервом",IF(Q15<P15,"Оправданы (затраты < ожид. потерь)","Пересмотреть меры")) -> Оправданы (затраты < ожид. потерь) | S15: 0.1 | T15: 0.7 | U15: =S15*T15 -> 0.07 | V15: =IF(U15>'Шкалы оценки'!$B$21,"Высокий",IF(U15>='Шкалы оценки'!$B$22,"Средний","Низкий")) -> Низкий | W15: =RANK(I15,$I$5:$I$23)+COUNTIF($I$5:I15,I15)-1 -> 10
A16: 12 | B16: ="R"&A16 -> R12 | C16: Не удастся привлечь 10–20 пилотных пользователей с реальными финмоделями | D16: Организационный | E16: Нерепрезентативный eval-набор, правила настроены «вслепую» | F16: К концу 2-го месяца < 5 пилотных пользователей | G16: 0.3 | H16: 0.8 | I16: =G16*H16 -> 0.24 | J16: =IF(I16>'Шкалы оценки'!$B$21,"Высокий",IF(I16>='Шкалы оценки'!$B$22,"Средний","Низкий")) -> Средний | K16: Снижение | L16: Прямой выход на бухгалтерские и консалтинговые фирмы, бесплатный аудит шаблона, открытые финмодели как резерв | M16: Руководитель проекта | N16: 1.0, 5.0 | O16: 35000 | P16: =G16*O16 -> 10500 | Q16: 2000 | R16: =IF(K16="Принятие","Принятие: покрывается резервом",IF(Q16<P16,"Оправданы (затраты < ожид. потерь)","Пересмотреть меры")) -> Оправданы (затраты < ожид. потерь) | S16: 0.2 | T16: 0.6 | U16: =S16*T16 -> 0.12 | V16: =IF(U16>'Шкалы оценки'!$B$21,"Высокий",IF(U16>='Шкалы оценки'!$B$22,"Средний","Низкий")) -> Низкий | W16: =RANK(I16,$I$5:$I$23)+COUNTIF($I$5:I16,I16)-1 -> 14
... A23: 19 | B23: ="R"&A23 -> R19 | C23: Временная недоступность провайдера LLM | D23: Технический | E23: Нет AI-объяснений и Cmd-K на время сбоя | F23: Ошибки или таймауты API > 5% за час | G23: 0.4 | H23: 0.3 | I23: =G23*H23 -> 0.12 | J23: =IF(I23>'Шкалы оценки'!$B$21,"Высокий",IF(I23>='Шкалы оценки'!$B$22,"Средний","Низкий")) -> Низкий | K23: Принятие | L23: Проверки работают без LLM; шаблонные объяснения из каталога правил; переключение провайдера в gateway | M23: ML/LLM-инженер | N23: 10.0 | O23: 6000 | P23: =G23*O23 -> 2400 | Q23: 1500 | R23: =IF(K23="Принятие","Принятие: покрывается резервом",IF(Q23<P23,"Оправданы (затраты < ожид. потерь)","Пересмотреть меры")) -> Принятие: покрывается резервом | S23: 0.4 | T23: 0.2 | U23: =S23*T23 -> 0.08 | V23: =IF(U23>'Шкалы оценки'!$B$21,"Высокий",IF(U23>='Шкалы оценки'!$B$22,"Средний","Низкий")) -> Низкий | W23: =RANK(I23,$I$5:$I$23)+COUNTIF($I$5:I23,I23)-1 -> 19
C24: Итого | P24: =SUM(P5:P23) -> 323100 | Q24: =SUM(Q5:Q23) -> 60500
C25: Сводка
C26: Рисков высокого приоритета | D26: =COUNTIF(J5:J23,"Высокий") -> 4
C27: Рисков среднего приоритета | D27: =COUNTIF(J5:J23,"Средний") -> 13
C28: Рисков низкого приоритета | D28: =COUNTIF(J5:J23,"Низкий") -> 2
C29: Средний коэффициент K до мер | D29: =AVERAGE(I5:I23) -> 0.32526316
C30: Средний коэффициент K после мер | D30: =AVERAGE(U5:U23) -> 0.14210526
C31: Снижение суммарного риска, % | D31: =1-SUM(U5:U23)/SUM(I5:I23) -> 0.5631068
C32: Затраты на меры (заложены в статьи бюджета как работы WBS), BYN | D32: =Q24 -> 60500
C33: Резерв на риски (10% от базовой стоимости), BYN | D33: 47000
C34: Ожидаемые потери по принятым рискам, BYN | D34: =SUMIF(K5:K23,"Принятие",P5:P23) -> 12400
C35: Резерв покрывает принятые риски? | D35: =IF(D34<=D33,"ДА","НЕТ") -> ДА
C37: Возможности (положительные риски)
B38: Код | C38: Возможность | D38: Эффект для проекта | E38: Триггер | F38: Вероятность | G38: Стратегия
B39: В.1 | C39: Партнёрство с бухгалтерскими и консалтинговыми фирмами | D39: +20–30 платящих мест по тарифу Team | E39: Две и более фирмы бесплатно проверили свой шаблон | F39: 0.4 | G39: Использование: пилот Team со скидкой, совместные кейсы
B40: В.2 | C40: Спрос AI-компаний на проверку через API / MCP | D40: Новый B2B-канал, защита от конкуренции встроенных ассистентов | E40: Запросы на API от бета-пользователей и интеграторов | F40: 0.3 | G40: Усиление: вынести API раньше, в начало v2
B41: В.3 | C41: AI-агенты для кодирования ускорят типовые работы | D41: Сокращение сроков обвязки бэкенда и фронтенда на 20–30% | E41: Скорость закрытия задач выше плана на воротах 2 | F41: 0.6 | G41: Использование: высвободившееся время — в резерв критического пути

Sheet Шкалы оценки
A1: Шкалы качественной оценки рисков проекта TableMind (бюджет 517 000 BYN, срок 12 месяцев)
A3: Шкала вероятности (P, от 0 до 1)
A4: Оценка P | B4: Описание | C4: Пример для проекта | D4: Вероятность наступления
A5: 0,1–0,2 | B5: Очень низкая | C5: Единичный случай в отрасли | D5: < 20%
A6: 0,2–0,4 | B6: Низкая | C6: Возможно, но маловероятно за год | D6: 20–40%
A7: 0,4–0,6 | B7: Средняя | C7: Случается примерно в половине похожих проектов | D7: 40–60%
A8: 0,6–0,8 | B8: Высокая | C8: Скорее произойдёт, есть явные признаки | D8: 60–80%
A9: 0,8–1,0 | B9: Очень высокая | C9: Почти наверняка | D9: > 80%
A11: Шкала воздействия (I, от 0 до 1)
A12: Оценка I | B12: Описание | C12: Финансовые потери | D12: Сроки | E12: Репутация / качество | F12: Юридические последствия
A13: 0,1–0,2 | B13: Очень низкое | C13: < 5 000 BYN (< 1% бюджета) | D13: задержка < 1 недели | E13: незаметно пользователям | F13: нет
A14: 0,3–0,4 | B14: Низкое | C14: 5 000–15 000 BYN | D14: до 2 недель | E14: единичные жалобы | F14: предписание без штрафа
A15: 0,5–0,6 | B15: Среднее | C15: 15 000–30 000 BYN | D15: до 1 месяца | E15: снижение метрик беты | F15: штраф по Закону № 99-З
A16: 0,7–0,8 | B16: Высокое | C16: 30 000–60 000 BYN | D16: 1–2 месяца, срыв ворот | E16: срыв критерия приёмки, отток | F16: проверка регулятора (НЦЗПД, надзор ЕС)
A17: 0,9–1,0 | B17: Очень высокое | C17: > 60 000 BYN | D17: срыв проекта | E17: потеря доверия рынка | F17: штраф GDPR, блокировка обработки
A19: Приоритет риска по коэффициенту K = P × I (пороги — как в шаблоне «Карта рисков в Excel»: 0,505 и 0,14)
A20: Приоритет | B20: Порог K | C20: Действие
A21: Высокий (K > 0,505) | B21: 0.505 | C21: Обязательные меры, еженедельный мониторинг, владелец — член команды
A22: Средний (0,14 ≤ K ≤ 0,505) | B22: 0.14 | C22: Меры при экономической целесообразности, мониторинг на воротах
A23: Низкий (K < 0,14) | B23: 0 | C23: Принятие, контроль по триггеру
A25: Методы реагирования (PMBOK): уклонение — изменить план и исключить угрозу; снижение — уменьшить вероятность и/или последствия; передача — переложить последствия на третью сторону (договор, страхование); принятие — осознанно оставить риск и покрыть его резервом.

Sheet Карта рисков
A1: Карта рисков проекта TableMind (вероятность × воздействие)
A2: Сетка 0,1 × 0,1, как «3 вариант» в шаблоне: в ячейке — риски с такими P и I (формулы из «Реестра рисков»). Цвет — по K = P × I: > 0,505 высокий, 0,14–0,505 средний, < 0,14 низкий.
B4: I ↓ / P →
A5: Сила воздействия риска I | B5: 1 | C5: =TRIM(IF(AND(ABS('Реестр рисков'!$G$5-0.1)<0.001,ABS('Реестр рисков'!$H$5-1)<0.001),'Реестр рисков'!$B$5&" ","")&IF(AND(ABS('Реестр рисков'!$G$6-0.1)<0.001,ABS('Реестр рисков'!$H$6-1)<0.001),'Реестр рисков'!$B$6&" ","")&IF(AND(ABS('Реестр рисков'!$G$7-0.1)<0.001,ABS('Реестр рисков'!$H$7-1)<0.001),'Реестр рисков'!$B$7&" ","")&IF(AND(ABS('Реестр рисков'!$G$8-0.1)<0.001,ABS('Реестр рисков'!$H$8-1)<0.001),'Реестр рисков'!$B$8&" ","")&IF(AND(ABS('Реестр рисков'!$G$9-0.1)<0.001,ABS('Реестр рисков'!$H$9-1)<0.001),'Реестр рисков'!$B$9&" ","")&IF(AND(ABS('Реестр рисков'!$G$10-0.1)<0.001,ABS('Реестр рисков'!$H$10-1)<0.001),'Реестр рисков'!$B$10&" ","")&IF(AND(ABS('Реестр рисков'!$G$11-0.1)<0.001,ABS('Реестр рисков'!$H$11-1)<0.001),'Реестр рисков'!$B$11&" ","")&IF(AND(ABS('Реестр рисков'!$G$12-0.1)<0.001,ABS('Реестр рисков'!$H$12-1)<0.001),'Реестр рисков'!$B$12&" ","")&IF(AND(ABS('Реестр рисков'!$G$13-0.1)<0.001,ABS('Реестр рисков'!$H$13-1)<0.001),'Реестр рисков'!$B$13&" ","")&IF(AND(ABS('Реестр рисков'!$G$14-0.1)<0.001,ABS('Реестр рисков'!$H$14-1)<0.001),'Реестр рисков'!$B$14&" ","")&IF(AND(ABS('Реестр рисков'!$G$15-0.1)<0.001,ABS('Реестр рисков'!$H$15-1)<0.001),'Реестр рисков'!$B$15&" ","")&IF(AND(ABS('Реестр рисков'!$G$16-0.1)<0.001,ABS('Реестр рисков'!$H$16-1)<0.001),'Реестр рисков'!$B$16&" ","")&IF(AND(ABS('Реестр рисков'!$G$17-0.1)<0.001,ABS('Реестр рисков'!$H$17-1)<0.001),'Реестр рисков'!$B$17&" ","")&IF(AND(ABS('Реестр рисков'!$G$18-0.1)<0.001,ABS('Реестр рисков'!$H$18-1)<0.001),'Реестр рисков'!$B$18&" ","")&IF(AND(ABS('Реестр рисков'!$G$19-0.1)<0.001,ABS('Реестр рисков'!$H$19-1)<0.001),'Реестр рисков'!$B$19&" ","")&IF(AND(ABS('Реестр рисков'!$G$20-0.1)<0.001,ABS('Реестр рисков'!$H$20-1)<0.001),'Реестр рисков'!$B$20&" ","")&IF(AND(ABS('Реестр рисков'!$G$21-0.1)<0.001,ABS('Реестр рисков'!$H$21-1)<0.001),'Реестр рисков'!$B$21&" ","")&IF(AND(ABS('Реестр рисков'!$G$22-0.1)<0.001,ABS('Реестр рисков'!$H$22-1)<0.001),'Реестр рисков'!$B$22&" ","")&IF(AND(ABS('Реестр рисков'!$G$23-0.1)<0.001,ABS('Реестр рисков'!$H$23-1)<0.001),'Реестр рисков'!$B$23&" ","")) | D5: =TRIM(IF(AND(ABS('Реестр рисков'!$G$5-0.2)<0.001,ABS('Реестр рисков'!$H$5-1)<0.001),'Реестр рисков'!$B$5&" ","")&IF(AND(ABS('Реестр рисков'!$G$6-0.2)<0.001,ABS('Реестр рисков'!$H$6-1)<0.001),'Реестр рисков'!$B$6&" ","")&IF(AND(ABS('Реестр рисков'!$G$7-0.2)<0.001,ABS('Реестр рисков'!$H$7-1)<0.001),'Реестр рисков'!$B$7&" ","")&IF(AND(ABS('Реестр рисков'!$G$8-0.2)<0.001,ABS('Реестр рисков'!$H$8-1)<0.001),'Реестр рисков'!$B$8&" ","")&IF(AND(ABS('Реестр рисков'!$G$9-0.2)<0.001,ABS('Реестр рисков'!$H$9-1)<0.001),'Реестр рисков'!$B$9&" ","")&IF(AND(ABS('Реестр рисков'!$G$10-0.2)<0.001,ABS('Реестр рисков'!$H$10-1)<0.001),'Реестр рисков'!$B$10&" ","")&IF(AND(ABS('Реестр рисков'!$G$11-0.2)<0.001,ABS('Реестр рисков'!$H$11-1)<0.001),'Реестр рисков'!$B$11&" ","")&IF(AND(ABS('Реестр рисков'!$G$12-0.2)<0.001,ABS('Реестр рисков'!$H$12-1)<0.001),'Реестр рисков'!$B$12&" ","")&IF(AND(ABS('Реестр рисков'!$G$13-0.2)<0.001,ABS('Реестр рисков'!$H$13-1)<0.001),'Реестр рисков'!$B$13&" ","")&IF(AND(ABS('Реестр рисков'!$G$14-0.2)<0.001,ABS('Реестр рисков'!$H$14-1)<0.001),'Реестр рисков'!$B$14&" ","")&IF(AND(ABS('Реестр рисков'!$G$15-0.2)<0.001,ABS('Реестр рисков'!$H$15-1)<0.001),'Реестр рисков'!$B$15&" ","")&IF(AND(ABS('Реестр рисков'!$G$16-0.2)<0.001,ABS('Реестр рисков'!$H$16-1)<0.001),'Реестр рисков'!$B$16&" ","")&IF(AND(ABS('Реестр рисков'!$G$17-0.2)<0.001,ABS('Реестр рисков'!$H$17-1)<0.001),'Реестр рисков'!$B$17&" ","")&IF(AND(ABS('Реестр рисков'!$G$18-0.2)<0.001,ABS('Реестр рисков'!$H$18-1)<0.001),'Реестр рисков'!$B$18&" ","")&IF(AND(ABS('Реестр рисков'!$G$19-0.2)<0.001,ABS('Реестр рисков'!$H$19-1)<0.001),'Реестр рисков'!$B$19&" ","")&IF(AND(ABS('Реестр рисков'!$G$20-0.2)<0.001,ABS('Реестр рисков'!$H$20-1)<0.001),'Реестр рисков'!$B$20&" ","")&IF(AND(ABS('Реестр рисков'!$G$21-0.2)<0.001,ABS('Реестр рисков'!$H$21-1)<0.001),'Реестр рисков'!$B$21&" ","")&IF(AND(ABS('Реестр рисков'!$G$22-0.2)<0.001,ABS('Реестр рисков'!$H$22-1)<0.001),'Реестр рисков'!$B$22&" ","")&IF(AND(ABS('Реестр рисков'!$G$23-0.2)<0.001,ABS('Реестр рисков'!$H$23-1)<0.001),'Реестр рисков'!$B$23&" ","")) -> R16 | E5: =TRIM(IF(AND(ABS('Реестр рисков'!$G$5-0.3)<0.001,ABS('Реестр рисков'!$H$5-1)<0.001),'Реестр рисков'!$B$5&" ","")&IF(AND(ABS('Реестр рисков'!$G$6-0.3)<0.001,ABS('Реестр рисков'!$H$6-1)<0.001),'Реестр рисков'!$B$6&" ","")&IF(AND(ABS('Реестр рисков'!$G$7-0.3)<0.001,ABS('Реестр рисков'!$H$7-1)<0.001),'Реестр рисков'!$B$7&" ","")&IF(AND(ABS('Реестр рисков'!$G$8-0.3)<0.001,ABS('Реестр рисков'!$H$8-1)<0.001),'Реестр рисков'!$B$8&" ","")&IF(AND(ABS('Реестр рисков'!$G$9-0.3)<0.001,ABS('Реестр рисков'!$H$9-1)<0.001),'Реестр рисков'!$B$9&" ","")&IF(AND(ABS('Реестр рисков'!$G$10-0.3)<0.001,ABS('Реестр рисков'!$H$10-1)<0.001),'Реестр рисков'!$B$10&" ","")&IF(AND(ABS('Реестр рисков'!$G$11-0.3)<0.001,ABS('Реестр рисков'!$H$11-1)<0.001),'Реестр рисков'!$B$11&" ","")&IF(AND(ABS('Реестр рисков'!$G$12-0.3)<0.001,ABS('Реестр рисков'!$H$12-1)<0.001),'Реестр рисков'!$B$12&" ","")&IF(AND(ABS('Реестр рисков'!$G$13-0.3)<0.001,ABS('Реестр рисков'!$H$13-1)<0.001),'Реестр рисков'!$B$13&" ","")&IF(AND(ABS('Реестр рисков'!$G$14-0.3)<0.001,ABS('Реестр рисков'!$H$14-1)<0.001),'Реестр рисков'!$B$14&" ","")&IF(AND(ABS('Реестр рисков'!$G$15-0.3)<0.001,ABS('Реестр рисков'!$H$15-1)<0.001),'Реестр рисков'!$B$15&" ","")&IF(AND(ABS('Реестр рисков'!$G$16-0.3)<0.001,ABS('Реестр рисков'!$H$16-1)<0.001),'Реестр рисков'!$B$16&" ","")&IF(AND(ABS('Реестр рисков'!$G$17-0.3)<0.001,ABS('Реестр рисков'!$H$17-1)<0.001),'Реестр рисков'!$B$17&" ","")&IF(AND(ABS('Реестр рисков'!$G$18-0.3)<0.001,ABS('Реестр рисков'!$H$18-1)<0.001),'Реестр рисков'!$B$18&" ","")&IF(AND(ABS('Реестр рисков'!$G$19-0.3)<0.001,ABS('Реестр рисков'!$H$19-1)<0.001),'Реестр рисков'!$B$19&" ","")&IF(AND(ABS('Реестр рисков'!$G$20-0.3)<0.001,ABS('Реестр рисков'!$H$20-1)<0.001),'Реестр рисков'!$B$20&" ","")&IF(AND(ABS('Реестр рисков'!$G$21-0.3)<0.001,ABS('Реестр рисков'!$H$21-1)<0.001),'Реестр рисков'!$B$21&" ","")&IF(AND(ABS('Реестр рисков'!$G$22-0.3)<0.001,ABS('Реестр рисков'!$H$22-1)<0.001),'Реестр рисков'!$B$22&" ","")&IF(AND(ABS('Реестр рисков'!$G$23-0.3)<0.001,ABS('Реестр рисков'!$H$23-1)<0.001),'Реестр рисков'!$B$23&" ","")) | F5: =TRIM(IF(AND(ABS('Реестр рисков'!$G$5-0.4)<0.001,ABS('Реестр рисков'!$H$5-1)<0.001),'Реестр рисков'!$B$5&" ","")&IF(AND(ABS('Реестр рисков'!$G$6-0.4)<0.001,ABS('Реестр рисков'!$H$6-1)<0.001),'Реестр рисков'!$B$6&" ","")&IF(AND(ABS('Реестр рисков'!$G$7-0.4)<0.001,ABS('Реестр рисков'!$H$7-1)<0.001),'Реестр рисков'!$B$7&" ","")&IF(AND(ABS('Реестр рисков'!$G$8-0.4)<0.001,ABS('Реестр рисков'!$H$8-1)<0.001),'Реестр рисков'!$B$8&" ","")&IF(AND(ABS('Реестр рисков'!$G$9-0.4)<0.001,ABS('Реестр рисков'!$H$9-1)<0.001),'Реестр рисков'!$B$9&" ","")&IF(AND(ABS('Реестр рисков'!$G$10-0.4)<0.001,ABS('Реестр рисков'!$H$10-1)<0.001),'Реестр рисков'!$B$10&" ","")&IF(AND(ABS('Реестр рисков'!$G$11-0.4)<0.001,ABS('Реестр рисков'!$H$11-1)<0.001),'Реестр рисков'!$B$11&" ","")&IF(AND(ABS('Реестр рисков'!$G$12-0.4)<0.001,ABS('Реестр рисков'!$H$12-1)<0.001),'Реестр рисков'!$B$12&" ","")&IF(AND(ABS('Реестр рисков'!$G$13-0.4)<0.001,ABS('Реестр рисков'!$H$13-1)<0.001),'Реестр рисков'!$B$13&" ","")&IF(AND(ABS('Реестр рисков'!$G$14-0.4)<0.001,ABS('Реестр рисков'!$H$14-1)<0.001),'Реестр рисков'!$B$14&" ","")&IF(AND(ABS('Реестр рисков'!$G$15-0.4)<0.001,ABS('Реестр рисков'!$H$15-1)<0.001),'Реестр рисков'!$B$15&" ","")&IF(AND(ABS('Реестр рисков'!$G$16-0.4)<0.001,ABS('Реестр рисков'!$H$16-1)<0.001),'Реестр рисков'!$B$16&" ","")&IF(AND(ABS('Реестр рисков'!$G$17-0.4)<0.001,ABS('Реестр рисков'!$H$17-1)<0.001),'Реестр рисков'!$B$17&" ","")&IF(AND(ABS('Реестр рисков'!$G$18-0.4)<0.001,ABS('Реестр рисков'!$H$18-1)<0.001),'Реестр рисков'!$B$18&" ","")&IF(AND(ABS('Реестр рисков'!$G$19-0.4)<0.001,ABS('Реестр рисков'!$H$19-1)<0.001),'Реестр рисков'!$B$19&" ","")&IF(AND(ABS('Реестр рисков'!$G$20-0.4)<0.001,ABS('Реестр рисков'!$H$20-1)<0.001),'Реестр рисков'!$B$20&" ","")&IF(AND(ABS('Реестр рисков'!$G$21-0.4)<0.001,ABS('Реестр рисков'!$H$21-1)<0.001),'Реестр рисков'!$B$21&" ","")&IF(AND(ABS('Реестр рисков'!$G$22-0.4)<0.001,ABS('Реестр рисков'!$H$22-1)<0.001),'Реестр рисков'!$B$22&" ","")&IF(AND(ABS('Реестр рисков'!$G$23-0.4)<0.001,ABS('Реестр рисков'!$H$23-1)<0.001),'Реестр рисков'!$B$23&" ","")) | G5: =TRIM(IF(AND(ABS('Реестр рисков'!$G$5-0.5)<0.001,ABS('Реестр рисков'!$H$5-1)<0.001),'Реестр рисков'!$B$5&" ","")&IF(AND(ABS('Реестр рисков'!$G$6-0.5)<0.001,ABS('Реестр рисков'!$H$6-1)<0.001),'Реестр рисков'!$B$6&" ","")&IF(AND(ABS('Реестр рисков'!$G$7-0.5)<0.001,ABS('Реестр рисков'!$H$7-1)<0.001),'Реестр рисков'!$B$7&" ","")&IF(AND(ABS('Реестр рисков'!$G$8-0.5)<0.001,ABS('Реестр рисков'!$H$8-1)<0.001),'Реестр рисков'!$B$8&" ","")&IF(AND(ABS('Реестр рисков'!$G$9-0.5)<0.001,ABS('Реестр рисков'!$H$9-1)<0.001),'Реестр рисков'!$B$9&" ","")&IF(AND(ABS('Реестр рисков'!$G$10-0.5)<0.001,ABS('Реестр рисков'!$H$10-1)<0.001),'Реестр рисков'!$B$10&" ","")&IF(AND(ABS('Реестр рисков'!$G$11-0.5)<0.001,ABS('Реестр рисков'!$H$11-1)<0.001),'Реестр рисков'!$B$11&" ","")&IF(AND(ABS('Реестр рисков'!$G$12-0.5)<0.001,ABS('Реестр рисков'!$H$12-1)<0.001),'Реестр рисков'!$B$12&" ","")&IF(AND(ABS('Реестр рисков'!$G$13-0.5)<0.001,ABS('Реестр рисков'!$H$13-1)<0.001),'Реестр рисков'!$B$13&" ","")&IF(AND(ABS('Реестр рисков'!$G$14-0.5)<0.001,ABS('Реестр рисков'!$H$14-1)<0.001),'Реестр рисков'!$B$14&" ","")&IF(AND(ABS('Реестр рисков'!$G$15-0.5)<0.001,ABS('Реестр рисков'!$H$15-1)<0.001),'Реестр рисков'!$B$15&" ","")&IF(AND(ABS('Реестр рисков'!$G$16-0.5)<0.001,ABS('Реестр рисков'!$H$16-1)<0.001),'Реестр рисков'!$B$16&" ","")&IF(AND(ABS('Реестр рисков'!$G$17-0.5)<0.001,ABS('Реестр рисков'!$H$17-1)<0.001),'Реестр рисков'!$B$17&" ","")&IF(AND(ABS('Реестр рисков'!$G$18-0.5)<0.001,ABS('Реестр рисков'!$H$18-1)<0.001),'Реестр рисков'!$B$18&" ","")&IF(AND(ABS('Реестр рисков'!$G$19-0.5)<0.001,ABS('Реестр рисков'!$H$19-1)<0.001),'Реестр рисков'!$B$19&" ","")&IF(AND(ABS('Реестр рисков'!$G$20-0.5)<0.001,ABS('Реестр рисков'!$H$20-1)<0.001),'Реестр рисков'!$B$20&" ","")&IF(AND(ABS('Реестр рисков'!$G$21-0.5)<0.001,ABS('Реестр рисков'!$H$21-1)<0.001),'Реестр рисков'!$B$21&" ","")&IF(AND(ABS('Реестр рисков'!$G$22-0.5)<0.001,ABS('Реестр рисков'!$H$22-1)<0.001),'Реестр рисков'!$B$22&" ","")&IF(AND(ABS('Реестр рисков'!$G$23-0.5)<0.001,ABS('Реестр рисков'!$H$23-1)<0.001),'Реестр рисков'!$B$23&" ","")) | H5: =TRIM(IF(AND(ABS('Реестр рисков'!$G$5-0.6)<0.001,ABS('Реестр рисков'!$H$5-1)<0.001),'Реестр рисков'!$B$5&" ","")&IF(AND(ABS('Реестр рисков'!$G$6-0.6)<0.001,ABS('Реестр рисков'!$H$6-1)<0.001),'Реестр рисков'!$B$6&" ","")&IF(AND(ABS('Реестр рисков'!$G$7-0.6)<0.001,ABS('Реестр рисков'!$H$7-1)<0.001),'Реестр рисков'!$B$7&" ","")&IF(AND(ABS('Реестр рисков'!$G$8-0.6)<0.001,ABS('Реестр рисков'!$H$8-1)<0.001),'Реестр рисков'!$B$8&" ","")&IF(AND(ABS('Реестр рисков'!$G$9-0.6)<0.001,ABS('Реестр рисков'!$H$9-1)<0.001),'Реестр рисков'!$B$9&" ","")&IF(AND(ABS('Реестр рисков'!$G$10-0.6)<0.001,ABS('Реестр рисков'!$H$10-1)<0.001),'Реестр рисков'!$B$10&" ","")&IF(AND(ABS('Реестр рисков'!$G$11-0.6)<0.001,ABS('Реестр рисков'!$H$11-1)<0.001),'Реестр рисков'!$B$11&" ","")&IF(AND(ABS('Реестр рисков'!$G$12-0.6)<0.001,ABS('Реестр рисков'!$H$12-1)<0.001),'Реестр рисков'!$B$12&" ","")&IF(AND(ABS('Реестр рисков'!$G$13-0.6)<0.001,ABS('Реестр рисков'!$H$13-1)<0.001),'Реестр рисков'!$B$13&" ","")&IF(AND(ABS('Реестр рисков'!$G$14-0.6)<0.001,ABS('Реестр рисков'!$H$14-1)<0.001),'Реестр рисков'!$B$14&" ","")&IF(AND(ABS('Реестр рисков'!$G$15-0.6)<0.001,ABS('Реестр рисков'!$H$15-1)<0.001),'Реестр рисков'!$B$15&" ","")&IF(AND(ABS('Реестр рисков'!$G$16-0.6)<0.001,ABS('Реестр рисков'!$H$16-1)<0.001),'Реестр рисков'!$B$16&" ","")&IF(AND(ABS('Реестр рисков'!$G$17-0.6)<0.001,ABS('Реестр рисков'!$H$17-1)<0.001),'Реестр рисков'!$B$17&" ","")&IF(AND(ABS('Реестр рисков'!$G$18-0.6)<0.001,ABS('Реестр рисков'!$H$18-1)<0.001),'Реестр рисков'!$B$18&" ","")&IF(AND(ABS('Реестр рисков'!$G$19-0.6)<0.001,ABS('Реестр рисков'!$H$19-1)<0.001),'Реестр рисков'!$B$19&" ","")&IF(AND(ABS('Реестр рисков'!$G$20-0.6)<0.001,ABS('Реестр рисков'!$H$20-1)<0.001),'Реестр рисков'!$B$20&" ","")&IF(AND(ABS('Реестр рисков'!$G$21-0.6)<0.001,ABS('Реестр рисков'!$H$21-1)<0.001),'Реестр рисков'!$B$21&" ","")&IF(AND(ABS('Реестр рисков'!$G$22-0.6)<0.001,ABS('Реестр рисков'!$H$22-1)<0.001),'Реестр рисков'!$B$22&" ","")&IF(AND(ABS('Реестр рисков'!$G$23-0.6)<0.001,ABS('Реестр рисков'!$H$23-1)<0.001),'Реестр рисков'!$B$23&" ","")) | I5: =TRIM(IF(AND(ABS('Реестр рисков'!$G$5-0.7)<0.001,ABS('Реестр рисков'!$H$5-1)<0.001),'Реестр рисков'!$B$5&" ","")&IF(AND(ABS('Реестр рисков'!$G$6-0.7)<0.001,ABS('Реестр рисков'!$H$6-1)<0.001),'Реестр рисков'!$B$6&" ","")&IF(AND(ABS('Реестр рисков'!$G$7-0.7)<0.001,ABS('Реестр рисков'!$H$7-1)<0.001),'Реестр рисков'!$B$7&" ","")&IF(AND(ABS('Реестр рисков'!$G$8-0.7)<0.001,ABS('Реестр рисков'!$H$8-1)<0.001),'Реестр рисков'!$B$8&" ","")&IF(AND(ABS('Реестр рисков'!$G$9-0.7)<0.001,ABS('Реестр рисков'!$H$9-1)<0.001),'Реестр рисков'!$B$9&" ","")&IF(AND(ABS('Реестр рисков'!$G$10-0.7)<0.001,ABS('Реестр рисков'!$H$10-1)<0.001),'Реестр рисков'!$B$10&" ","")&IF(AND(ABS('Реестр рисков'!$G$11-0.7)<0.001,ABS('Реестр рисков'!$H$11-1)<0.001),'Реестр рисков'!$B$11&" ","")&IF(AND(ABS('Реестр рисков'!$G$12-0.7)<0.001,ABS('Реестр рисков'!$H$12-1)<0.001),'Реестр рисков'!$B$12&" ","")&IF(AND(ABS('Реестр рисков'!$G$13-0.7)<0.001,ABS('Реестр рисков'!$H$13-1)<0.001),'Реестр рисков'!$B$13&" ","")&IF(AND(ABS('Реестр рисков'!$G$14-0.7)<0.001,ABS('Реестр рисков'!$H$14-1)<0.001),'Реестр рисков'!$B$14&" ","")&IF(AND(ABS('Реестр рисков'!$G$15-0.7)<0.001,ABS('Реестр рисков'!$H$15-1)<0.001),'Реестр рисков'!$B$15&" ","")&IF(AND(ABS('Реестр рисков'!$G$16-0.7)<0.001,ABS('Реестр рисков'!$H$16-1)<0.001),'Реестр рисков'!$B$16&" ","")&IF(AND(ABS('Реестр рисков'!$G$17-0.7)<0.001,ABS('Реестр рисков'!$H$17-1)<0.001),'Реестр рисков'!$B$17&" ","")&IF(AND(ABS('Реестр рисков'!$G$18-0.7)<0.001,ABS('Реестр рисков'!$H$18-1)<0.001),'Реестр рисков'!$B$18&" ","")&IF(AND(ABS('Реестр рисков'!$G$19-0.7)<0.001,ABS('Реестр рисков'!$H$19-1)<0.001),'Реестр рисков'!$B$19&" ","")&IF(AND(ABS('Реестр рисков'!$G$20-0.7)<0.001,ABS('Реестр рисков'!$H$20-1)<0.001),'Реестр рисков'!$B$20&" ","")&IF(AND(ABS('Реестр рисков'!$G$21-0.7)<0.001,ABS('Реестр рисков'!$H$21-1)<0.001),'Реестр рисков'!$B$21&" ","")&IF(AND(ABS('Реестр рисков'!$G$22-0.7)<0.001,ABS('Реестр рисков'!$H$22-1)<0.001),'Реестр рисков'!$B$22&" ","")&IF(AND(ABS('Реестр рисков'!$G$23-0.7)<0.001,ABS('Реестр рисков'!$H$23-1)<0.001),'Реестр рисков'!$B$23&" ","")) | J5: =TRIM(IF(AND(ABS('Реестр рисков'!$G$5-0.8)<0.001,ABS('Реестр рисков'!$H$5-1)<0.001),'Реестр рисков'!$B$5&" ","")&IF(AND(ABS('Реестр рисков'!$G$6-0.8)<0.001,ABS('Реестр рисков'!$H$6-1)<0.001),'Реестр рисков'!$B$6&" ","")&IF(AND(ABS('Реестр рисков'!$G$7-0.8)<0.001,ABS('Реестр рисков'!$H$7-1)<0.001),'Реестр рисков'!$B$7&" ","")&IF(AND(ABS('Реестр рисков'!$G$8-0.8)<0.001,ABS('Реестр рисков'!$H$8-1)<0.001),'Реестр рисков'!$B$8&" ","")&IF(AND(ABS('Реестр рисков'!$G$9-0.8)<0.001,ABS('Реестр рисков'!$H$9-1)<0.001),'Реестр рисков'!$B$9&" ","")&IF(AND(ABS('Реестр рисков'!$G$10-0.8)<0.001,ABS('Реестр рисков'!$H$10-1)<0.001),'Реестр рисков'!$B$10&" ","")&IF(AND(ABS('Реестр рисков'!$G$11-0.8)<0.001,ABS('Реестр рисков'!$H$11-1)<0.001),'Реестр рисков'!$B$11&" ","")&IF(AND(ABS('Реестр рисков'!$G$12-0.8)<0.001,ABS('Реестр рисков'!$H$12-1)<0.001),'Реестр рисков'!$B$12&" ","")&IF(AND(ABS('Реестр рисков'!$G$13-0.8)<0.001,ABS('Реестр рисков'!$H$13-1)<0.001),'Реестр рисков'!$B$13&" ","")&IF(AND(ABS('Реестр рисков'!$G$14-0.8)<0.001,ABS('Реестр рисков'!$H$14-1)<0.001),'Реестр рисков'!$B$14&" ","")&IF(AND(ABS('Реестр рисков'!$G$15-0.8)<0.001,ABS('Реестр рисков'!$H$15-1)<0.001),'Реестр рисков'!$B$15&" ","")&IF(AND(ABS('Реестр рисков'!$G$16-0.8)<0.001,ABS('Реестр рисков'!$H$16-1)<0.001),'Реестр рисков'!$B$16&" ","")&IF(AND(ABS('Реестр рисков'!$G$17-0.8)<0.001,ABS('Реестр рисков'!$H$17-1)<0.001),'Реестр рисков'!$B$17&" ","")&IF(AND(ABS('Реестр рисков'!$G$18-0.8)<0.001,ABS('Реестр рисков'!$H$18-1)<0.001),'Реестр рисков'!$B$18&" ","")&IF(AND(ABS('Реестр рисков'!$G$19-0.8)<0.001,ABS('Реестр рисков'!$H$19-1)<0.001),'Реестр рисков'!$B$19&" ","")&IF(AND(ABS('Реестр рисков'!$G$20-0.8)<0.001,ABS('Реестр рисков'!$H$20-1)<0.001),'Реестр рисков'!$B$20&" ","")&IF(AND(ABS('Реестр рисков'!$G$21-0.8)<0.001,ABS('Реестр рисков'!$H$21-1)<0.001),'Реестр рисков'!$B$21&" ","")&IF(AND(ABS('Реестр рисков'!$G$22-0.8)<0.001,ABS('Реестр рисков'!$H$22-1)<0.001),'Реестр рисков'!$B$22&" ","")&IF(AND(ABS('Реестр рисков'!$G$23-0.8)<0.001,ABS('Реестр рисков'!$H$23-1)<0.001),'Реестр рисков'!$B$23&" ","")) | K5: =TRIM(IF(AND(ABS('Реестр рисков'!$G$5-0.9)<0.001,ABS('Реестр рисков'!$H$5-1)<0.001),'Реестр рисков'!$B$5&" ","")&IF(AND(ABS('Реестр рисков'!$G$6-0.9)<0.001,ABS('Реестр рисков'!$H$6-1)<0.001),'Реестр рисков'!$B$6&" ","")&IF(AND(ABS('Реестр рисков'!$G$7-0.9)<0.001,ABS('Реестр рисков'!$H$7-1)<0.001),'Реестр рисков'!$B$7&" ","")&IF(AND(ABS('Реестр рисков'!$G$8-0.9)<0.001,ABS('Реестр рисков'!$H$8-1)<0.001),'Реестр рисков'!$B$8&" ","")&IF(AND(ABS('Реестр рисков'!$G$9-0.9)<0.001,ABS('Реестр рисков'!$H$9-1)<0.001),'Реестр рисков'!$B$9&" ","")&IF(AND(ABS('Реестр рисков'!$G$10-0.9)<0.001,ABS('Реестр рисков'!$H$10-1)<0.001),'Реестр рисков'!$B$10&" ","")&IF(AND(ABS('Реестр рисков'!$G$11-0.9)<0.001,ABS('Реестр рисков'!$H$11-1)<0.001),'Реестр рисков'!$B$11&" ","")&IF(AND(ABS('Реестр рисков'!$G$12-0.9)<0.001,ABS('Реестр рисков'!$H$12-1)<0.001),'Реестр рисков'!$B$12&" ","")&IF(AND(ABS('Реестр рисков'!$G$13-0.9)<0.001,ABS('Реестр рисков'!$H$13-1)<0.001),'Реестр рисков'!$B$13&" ","")&IF(AND(ABS('Реестр рисков'!$G$14-0.9)<0.001,ABS('Реестр рисков'!$H$14-1)<0.001),'Реестр рисков'!$B$14&" ","")&IF(AND(ABS('Реестр рисков'!$G$15-0.9)<0.001,ABS('Реестр рисков'!$H$15-1)<0.001),'Реестр рисков'!$B$15&" ","")&IF(AND(ABS('Реестр рисков'!$G$16-0.9)<0.001,ABS('Реестр рисков'!$H$16-1)<0.001),'Реестр рисков'!$B$16&" ","")&IF(AND(ABS('Реестр рисков'!$G$17-0.9)<0.001,ABS('Реестр рисков'!$H$17-1)<0.001),'Реестр рисков'!$B$17&" ","")&IF(AND(ABS('Реестр рисков'!$G$18-0.9)<0.001,ABS('Реестр рисков'!$H$18-1)<0.001),'Реестр рисков'!$B$18&" ","")&IF(AND(ABS('Реестр рисков'!$G$19-0.9)<0.001,ABS('Реестр рисков'!$H$19-1)<0.001),'Реестр рисков'!$B$19&" ","")&IF(AND(ABS('Реестр рисков'!$G$20-0.9)<0.001,ABS('Реестр рисков'!$H$20-1)<0.001),'Реестр рисков'!$B$20&" ","")&IF(AND(ABS('Реестр рисков'!$G$21-0.9)<0.001,ABS('Реестр рисков'!$H$21-1)<0.001),'Реестр рисков'!$B$21&" ","")&IF(AND(ABS('Реестр рисков'!$G$22-0.9)<0.001,ABS('Реестр рисков'!$H$22-1)<0.001),'Реестр рисков'!$B$22&" ","")&IF(AND(ABS('Реестр рисков'!$G$23-0.9)<0.001,ABS('Реестр рисков'!$H$23-1)<0.001),'Реестр рисков'!$B$23&" ","")) | L5: =TRIM(IF(AND(ABS('Реестр рисков'!$G$5-1)<0.001,ABS('Реестр рисков'!$H$5-1)<0.001),'Реестр рисков'!$B$5&" ","")&IF(AND(ABS('Реестр рисков'!$G$6-1)<0.001,ABS('Реестр рисков'!$H$6-1)<0.001),'Реестр рисков'!$B$6&" ","")&IF(AND(ABS('Реестр рисков'!$G$7-1)<0.001,ABS('Реестр рисков'!$H$7-1)<0.001),'Реестр рисков'!$B$7&" ","")&IF(AND(ABS('Реестр рисков'!$G$8-1)<0.001,ABS('Реестр рисков'!$H$8-1)<0.001),'Реестр рисков'!$B$8&" ","")&IF(AND(ABS('Реестр рисков'!$G$9-1)<0.001,ABS('Реестр рисков'!$H$9-1)<0.001),'Реестр рисков'!$B$9&" ","")&IF(AND(ABS('Реестр рисков'!$G$10-1)<0.001,ABS('Реестр рисков'!$H$10-1)<0.001),'Реестр рисков'!$B$10&" ","")&IF(AND(ABS('Реестр рисков'!$G$11-1)<0.001,ABS('Реестр рисков'!$H$11-1)<0.001),'Реестр рисков'!$B$11&" ","")&IF(AND(ABS('Реестр рисков'!$G$12-1)<0.001,ABS('Реестр рисков'!$H$12-1)<0.001),'Реестр рисков'!$B$12&" ","")&IF(AND(ABS('Реестр рисков'!$G$13-1)<0.001,ABS('Реестр рисков'!$H$13-1)<0.001),'Реестр рисков'!$B$13&" ","")&IF(AND(ABS('Реестр рисков'!$G$14-1)<0.001,ABS('Реестр рисков'!$H$14-1)<0.001),'Реестр рисков'!$B$14&" ","")&IF(AND(ABS('Реестр рисков'!$G$15-1)<0.001,ABS('Реестр рисков'!$H$15-1)<0.001),'Реестр рисков'!$B$15&" ","")&IF(AND(ABS('Реестр рисков'!$G$16-1)<0.001,ABS('Реестр рисков'!$H$16-1)<0.001),'Реестр рисков'!$B$16&" ","")&IF(AND(ABS('Реестр рисков'!$G$17-1)<0.001,ABS('Реестр рисков'!$H$17-1)<0.001),'Реестр рисков'!$B$17&" ","")&IF(AND(ABS('Реестр рисков'!$G$18-1)<0.001,ABS('Реестр рисков'!$H$18-1)<0.001),'Реестр рисков'!$B$18&" ","")&IF(AND(ABS('Реестр рисков'!$G$19-1)<0.001,ABS('Реестр рисков'!$H$19-1)<0.001),'Реестр рисков'!$B$19&" ","")&IF(AND(ABS('Реестр рисков'!$G$20-1)<0.001,ABS('Реестр рисков'!$H$20-1)<0.001),'Реестр рисков'!$B$20&" ","")&IF(AND(ABS('Реестр рисков'!$G$21-1)<0.001,ABS('Реестр рисков'!$H$21-1)<0.001),'Реестр рисков'!$B$21&" ","")&IF(AND(ABS('Реестр рисков'!$G$22-1)<0.001,ABS('Реестр рисков'!$H$22-1)<0.001),'Реестр рисков'!$B$22&" ","")&IF(AND(ABS('Реестр рисков'!$G$23-1)<0.001,ABS('Реестр рисков'!$H$23-1)<0.001),'Реестр рисков'!$B$23&" ",""))
B6: 0.9 | C6: =TRIM(IF(AND(ABS('Реестр рисков'!$G$5-0.1)<0.001,ABS('Реестр рисков'!$H$5-0.9)<0.001),'Реестр рисков'!$B$5&" ","")&IF(AND(ABS('Реестр рисков'!$G$6-0.1)<0.001,ABS('Реестр рисков'!$H$6-0.9)<0.001),'Реестр рисков'!$B$6&" ","")&IF(AND(ABS('Реестр рисков'!$G$7-0.1)<0.001,ABS('Реестр рисков'!$H$7-0.9)<0.001),'Реестр рисков'!$B$7&" ","")&IF(AND(ABS('Реестр рисков'!$G$8-0.1)<0.001,ABS('Реестр рисков'!$H$8-0.9)<0.001),'Реестр рисков'!$B$8&" ","")&IF(AND(ABS('Реестр рисков'!$G$9-0.1)<0.001,ABS('Реестр рисков'!$H$9-0.9)<0.001),'Реестр рисков'!$B$9&" ","")&IF(AND(ABS('Реестр рисков'!$G$10-0.1)<0.001,ABS('Реестр рисков'!$H$10-0.9)<0.001),'Реестр рисков'!$B$10&" ","")&IF(AND(ABS('Реестр рисков'!$G$11-0.1)<0.001,ABS('Реестр рисков'!$H$11-0.9)<0.001),'Реестр рисков'!$B$11&" ","")&IF(AND(ABS('Реестр рисков'!$G$12-0.1)<0.001,ABS('Реестр рисков'!$H$12-0.9)<0.001),'Реестр рисков'!$B$12&" ","")&IF(AND(ABS('Реестр рисков'!$G$13-0.1)<0.001,ABS('Реестр рисков'!$H$13-0.9)<0.001),'Реестр рисков'!$B$13&" ","")&IF(AND(ABS('Реестр рисков'!$G$14-0.1)<0.001,ABS('Реестр рисков'!$H$14-0.9)<0.001),'Реестр рисков'!$B$14&" ","")&IF(AND(ABS('Реестр рисков'!$G$15-0.1)<0.001,ABS('Реестр рисков'!$H$15-0.9)<0.001),'Реестр рисков'!$B$15&" ","")&IF(AND(ABS('Реестр рисков'!$G$16-0.1)<0.001,ABS('Реестр рисков'!$H$16-0.9)<0.001),'Реестр рисков'!$B$16&" ","")&IF(AND(ABS('Реестр рисков'!$G$17-0.1)<0.001,ABS('Реестр рисков'!$H$17-0.9)<0.001),'Реестр рисков'!$B$17&" ","")&IF(AND(ABS('Реестр рисков'!$G$18-0.1)<0.001,ABS('Реестр рисков'!$H$18-0.9)<0.001),'Реестр рисков'!$B$18&" ","")&IF(AND(ABS('Реестр рисков'!$G$19-0.1)<0.001,ABS('Реестр рисков'!$H$19-0.9)<0.001),'Реестр рисков'!$B$19&" ","")&IF(AND(ABS('Реестр рисков'!$G$20-0.1)<0.001,ABS('Реестр рисков'!$H$20-0.9)<0.001),'Реестр рисков'!$B$20&" ","")&IF(AND(ABS('Реестр рисков'!$G$21-0.1)<0.001,ABS('Реестр рисков'!$H$21-0.9)<0.001),'Реестр рисков'!$B$21&" ","")&IF(AND(ABS('Реестр рисков'!$G$22-0.1)<0.001,ABS('Реестр рисков'!$H$22-0.9)<0.001),'Реестр рисков'!$B$22&" ","")&IF(AND(ABS('Реестр рисков'!$G$23-0.1)<0.001,ABS('Реестр рисков'!$H$23-0.9)<0.001),'Реестр рисков'!$B$23&" ","")) | D6: =TRIM(IF(AND(ABS('Реестр рисков'!$G$5-0.2)<0.001,ABS('Реестр рисков'!$H$5-0.9)<0.001),'Реестр рисков'!$B$5&" ","")&IF(AND(ABS('Реестр рисков'!$G$6-0.2)<0.001,ABS('Реестр рисков'!$H$6-0.9)<0.001),'Реестр рисков'!$B$6&" ","")&IF(AND(ABS('Реестр рисков'!$G$7-0.2)<0.001,ABS('Реестр рисков'!$H$7-0.9)<0.001),'Реестр рисков'!$B$7&" ","")&IF(AND(ABS('Реестр рисков'!$G$8-0.2)<0.001,ABS('Реестр рисков'!$H$8-0.9)<0.001),'Реестр рисков'!$B$8&" ","")&IF(AND(ABS('Реестр рисков'!$G$9-0.2)<0.001,ABS('Реестр рисков'!$H$9-0.9)<0.001),'Реестр рисков'!$B$9&" ","")&IF(AND(ABS('Реестр рисков'!$G$10-0.2)<0.001,ABS('Реестр рисков'!$H$10-0.9)<0.001),'Реестр рисков'!$B$10&" ","")&IF(AND(ABS('Реестр рисков'!$G$11-0.2)<0.001,ABS('Реестр рисков'!$H$11-0.9)<0.001),'Реестр рисков'!$B$11&" ","")&IF(AND(ABS('Реестр рисков'!$G$12-0.2)<0.001,ABS('Реестр рисков'!$H$12-0.9)<0.001),'Реестр рисков'!$B$12&" ","")&IF(AND(ABS('Реестр рисков'!$G$13-0.2)<0.001,ABS('Реестр рисков'!$H$13-0.9)<0.001),'Реестр рисков'!$B$13&" ","")&IF(AND(ABS('Реестр рисков'!$G$14-0.2)<0.001,ABS('Реестр рисков'!$H$14-0.9)<0.001),'Реестр рисков'!$B$14&" ","")&IF(AND(ABS('Реестр рисков'!$G$15-0.2)<0.001,ABS('Реестр рисков'!$H$15-0.9)<0.001),'Реестр рисков'!$B$15&" ","")&IF(AND(ABS('Реестр рисков'!$G$16-0.2)<0.001,ABS('Реестр рисков'!$H$16-0.9)<0.001),'Реестр рисков'!$B$16&" ","")&IF(AND(ABS('Реестр рисков'!$G$17-0.2)<0.001,ABS('Реестр рисков'!$H$17-0.9)<0.001),'Реестр рисков'!$B$17&" ","")&IF(AND(ABS('Реестр рисков'!$G$18-0.2)<0.001,ABS('Реестр рисков'!$H$18-0.9)<0.001),'Реестр рисков'!$B$18&" ","")&IF(AND(ABS('Реестр рисков'!$G$19-0.2)<0.001,ABS('Реестр рисков'!$H$19-0.9)<0.001),'Реестр рисков'!$B$19&" ","")&IF(AND(ABS('Реестр рисков'!$G$20-0.2)<0.001,ABS('Реестр рисков'!$H$20-0.9)<0.001),'Реестр рисков'!$B$20&" ","")&IF(AND(ABS('Реестр рисков'!$G$21-0.2)<0.001,ABS('Реестр рисков'!$H$21-0.9)<0.001),'Реестр рисков'!$B$21&" ","")&IF(AND(ABS('Реестр рисков'!$G$22-0.2)<0.001,ABS('Реестр рисков'!$H$22-0.9)<0.001),'Реестр рисков'!$B$22&" ","")&IF(AND(ABS('Реестр рисков'!$G$23-0.2)<0.001,ABS('Реестр рисков'!$H$23-0.9)<0.001),'Реестр рисков'!$B$23&" ","")) | E6: =TRIM(IF(AND(ABS('Реестр рисков'!$G$5-0.3)<0.001,ABS('Реестр рисков'!$H$5-0.9)<0.001),'Реестр рисков'!$B$5&" ","")&IF(AND(ABS('Реестр рисков'!$G$6-0.3)<0.001,ABS('Реестр рисков'!$H$6-0.9)<0.001),'Реестр рисков'!$B$6&" ","")&IF(AND(ABS('Реестр рисков'!$G$7-0.3)<0.001,ABS('Реестр рисков'!$H$7-0.9)<0.001),'Реестр рисков'!$B$7&" ","")&IF(AND(ABS('Реестр рисков'!$G$8-0.3)<0.001,ABS('Реестр рисков'!$H$8-0.9)<0.001),'Реестр рисков'!$B$8&" ","")&IF(AND(ABS('Реестр рисков'!$G$9-0.3)<0.001,ABS('Реестр рисков'!$H$9-0.9)<0.001),'Реестр рисков'!$B$9&" ","")&IF(AND(ABS('Реестр рисков'!$G$10-0.3)<0.001,ABS('Реестр рисков'!$H$10-0.9)<0.001),'Реестр рисков'!$B$10&" ","")&IF(AND(ABS('Реестр рисков'!$G$11-0.3)<0.001,ABS('Реестр рисков'!$H$11-0.9)<0.001),'Реестр рисков'!$B$11&" ","")&IF(AND(ABS('Реестр рисков'!$G$12-0.3)<0.001,ABS('Реестр рисков'!$H$12-0.9)<0.001),'Реестр рисков'!$B$12&" ","")&IF(AND(ABS('Реестр рисков'!$G$13-0.3)<0.001,ABS('Реестр рисков'!$H$13-0.9)<0.001),'Реестр рисков'!$B$13&" ","")&IF(AND(ABS('Реестр рисков'!$G$14-0.3)<0.001,ABS('Реестр рисков'!$H$14-0.9)<0.001),'Реестр рисков'!$B$14&" ","")&IF(AND(ABS('Реестр рисков'!$G$15-0.3)<0.001,ABS('Реестр рисков'!$H$15-0.9)<0.001),'Реестр рисков'!$B$15&" ","")&IF(AND(ABS('Реестр рисков'!$G$16-0.3)<0.001,ABS('Реестр рисков'!$H$16-0.9)<0.001),'Реестр рисков'!$B$16&" ","")&IF(AND(ABS('Реестр рисков'!$G$17-0.3)<0.001,ABS('Реестр рисков'!$H$17-0.9)<0.001),'Реестр рисков'!$B$17&" ","")&IF(AND(ABS('Реестр рисков'!$G$18-0.3)<0.001,ABS('Реестр рисков'!$H$18-0.9)<0.001),'Реестр рисков'!$B$18&" ","")&IF(AND(ABS('Реестр рисков'!$G$19-0.3)<0.001,ABS('Реестр рисков'!$H$19-0.9)<0.001),'Реестр рисков'!$B$19&" ","")&IF(AND(ABS('Реестр рисков'!$G$20-0.3)<0.001,ABS('Реестр рисков'!$H$20-0.9)<0.001),'Реестр рисков'!$B$20&" ","")&IF(AND(ABS('Реестр рисков'!$G$21-0.3)<0.001,ABS('Реестр рисков'!$H$21-0.9)<0.001),'Реестр рисков'!$B$21&" ","")&IF(AND(ABS('Реестр рисков'!$G$22-0.3)<0.001,ABS('Реестр рисков'!$H$22-0.9)<0.001),'Реестр рисков'!$B$22&" ","")&IF(AND(ABS('Реестр рисков'!$G$23-0.3)<0.001,ABS('Реестр рисков'!$H$23-0.9)<0.001),'Реестр рисков'!$B$23&" ","")) -> R13 | F6: =TRIM(IF(AND(ABS('Реестр рисков'!$G$5-0.4)<0.001,ABS('Реестр рисков'!$H$5-0.9)<0.001),'Реестр рисков'!$B$5&" ","")&IF(AND(ABS('Реестр рисков'!$G$6-0.4)<0.001,ABS('Реестр рисков'!$H$6-0.9)<0.001),'Реестр рисков'!$B$6&" ","")&IF(AND(ABS('Реестр рисков'!$G$7-0.4)<0.001,ABS('Реестр рисков'!$H$7-0.9)<0.001),'Реестр рисков'!$B$7&" ","")&IF(AND(ABS('Реестр рисков'!$G$8-0.4)<0.001,ABS('Реестр рисков'!$H$8-0.9)<0.001),'Реестр рисков'!$B$8&" ","")&IF(AND(ABS('Реестр рисков'!$G$9-0.4)<0.001,ABS('Реестр рисков'!$H$9-0.9)<0.001),'Реестр рисков'!$B$9&" ","")&IF(AND(ABS('Реестр рисков'!$G$10-0.4)<0.001,ABS('Реестр рисков'!$H$10-0.9)<0.001),'Реестр рисков'!$B$10&" ","")&IF(AND(ABS('Реестр рисков'!$G$11-0.4)<0.001,ABS('Реестр рисков'!$H$11-0.9)<0.001),'Реестр рисков'!$B$11&" ","")&IF(AND(ABS('Реестр рисков'!$G$12-0.4)<0.001,ABS('Реестр рисков'!$H$12-0.9)<0.001),'Реестр рисков'!$B$12&" ","")&IF(AND(ABS('Реестр рисков'!$G$13-0.4)<0.001,ABS('Реестр рисков'!$H$13-0.9)<0.001),'Реестр рисков'!$B$13&" ","")&IF(AND(ABS('Реестр рисков'!$G$14-0.4)<0.001,ABS('Реестр рисков'!$H$14-0.9)<0.001),'Реестр рисков'!$B$14&" ","")&IF(AND(ABS('Реестр рисков'!$G$15-0.4)<0.001,ABS('Реестр рисков'!$H$15-0.9)<0.001),'Реестр рисков'!$B$15&" ","")&IF(AND(ABS('Реестр рисков'!$G$16-0.4)<0.001,ABS('Реестр рисков'!$H$16-0.9)<0.001),'Реестр рисков'!$B$16&" ","")&IF(AND(ABS('Реестр рисков'!$G$17-0.4)<0.001,ABS('Реестр рисков'!$H$17-0.9)<0.001),'Реестр рисков'!$B$17&" ","")&IF(AND(ABS('Реестр рисков'!$G$18-0.4)<0.001,ABS('Реестр рисков'!$H$18-0.9)<0.001),'Реестр рисков'!$B$18&" ","")&IF(AND(ABS('Реестр рисков'!$G$19-0.4)<0.001,ABS('Реестр рисков'!$H$19-0.9)<0.001),'Реестр рисков'!$B$19&" ","")&IF(AND(ABS('Реестр рисков'!$G$20-0.4)<0.001,ABS('Реестр рисков'!$H$20-0.9)<0.001),'Реестр рисков'!$B$20&" ","")&IF(AND(ABS('Реестр рисков'!$G$21-0.4)<0.001,ABS('Реестр рисков'!$H$21-0.9)<0.001),'Реестр рисков'!$B$21&" ","")&IF(AND(ABS('Реестр рисков'!$G$22-0.4)<0.001,ABS('Реестр рисков'!$H$22-0.9)<0.001),'Реестр рисков'!$B$22&" ","")&IF(AND(ABS('Реестр рисков'!$G$23-0.4)<0.001,ABS('Реестр рисков'!$H$23-0.9)<0.001),'Реестр рисков'!$B$23&" ","")) | G6: =TRIM(IF(AND(ABS('Реестр рисков'!$G$5-0.5)<0.001,ABS('Реестр рисков'!$H$5-0.9)<0.001),'Реестр рисков'!$B$5&" ","")&IF(AND(ABS('Реестр рисков'!$G$6-0.5)<0.001,ABS('Реестр рисков'!$H$6-0.9)<0.001),'Реестр рисков'!$B$6&" ","")&IF(AND(ABS('Реестр рисков'!$G$7-0.5)<0.001,ABS('Реестр рисков'!$H$7-0.9)<0.001),'Реестр рисков'!$B$7&" ","")&IF(AND(ABS('Реестр рисков'!$G$8-0.5)<0.001,ABS('Реестр рисков'!$H$8-0.9)<0.001),'Реестр рисков'!$B$8&" ","")&IF(AND(ABS('Реестр рисков'!$G$9-0.5)<0.001,ABS('Реестр рисков'!$H$9-0.9)<0.001),'Реестр рисков'!$B$9&" ","")&IF(AND(ABS('Реестр рисков'!$G$10-0.5)<0.001,ABS('Реестр рисков'!$H$10-0.9)<0.001),'Реестр рисков'!$B$10&" ","")&IF(AND(ABS('Реестр рисков'!$G$11-0.5)<0.001,ABS('Реестр рисков'!$H$11-0.9)<0.001),'Реестр рисков'!$B$11&" ","")&IF(AND(ABS('Реестр рисков'!$G$12-0.5)<0.001,ABS('Реестр рисков'!$H$12-0.9)<0.001),'Реестр рисков'!$B$12&" ","")&IF(AND(ABS('Реестр рисков'!$G$13-0.5)<0.001,ABS('Реестр рисков'!$H$13-0.9)<0.001),'Реестр рисков'!$B$13&" ","")&IF(AND(ABS('Реестр рисков'!$G$14-0.5)<0.001,ABS('Реестр рисков'!$H$14-0.9)<0.001),'Реестр рисков'!$B$14&" ","")&IF(AND(ABS('Реестр рисков'!$G$15-0.5)<0.001,ABS('Реестр рисков'!$H$15-0.9)<0.001),'Реестр рисков'!$B$15&" ","")&IF(AND(ABS('Реестр рисков'!$G$16-0.5)<0.001,ABS('Реестр рисков'!$H$16-0.9)<0.001),'Реестр рисков'!$B$16&" ","")&IF(AND(ABS('Реестр рисков'!$G$17-0.5)<0.001,ABS('Реестр рисков'!$H$17-0.9)<0.001),'Реестр рисков'!$B$17&" ","")&IF(AND(ABS('Реестр рисков'!$G$18-0.5)<0.001,ABS('Реестр рисков'!$H$18-0.9)<0.001),'Реестр рисков'!$B$18&" ","")&IF(AND(ABS('Реестр рисков'!$G$19-0.5)<0.001,ABS('Реестр рисков'!$H$19-0.9)<0.001),'Реестр рисков'!$B$19&" ","")&IF(AND(ABS('Реестр рисков'!$G$20-0.5)<0.001,ABS('Реестр рисков'!$H$20-0.9)<0.001),'Реестр рисков'!$B$20&" ","")&IF(AND(ABS('Реестр рисков'!$G$21-0.5)<0.001,ABS('Реестр рисков'!$H$21-0.9)<0.001),'Реестр рисков'!$B$21&" ","")&IF(AND(ABS('Реестр рисков'!$G$22-0.5)<0.001,ABS('Реестр рисков'!$H$22-0.9)<0.001),'Реестр рисков'!$B$22&" ","")&IF(AND(ABS('Реестр рисков'!$G$23-0.5)<0.001,ABS('Реестр рисков'!$H$23-0.9)<0.001),'Реестр рисков'!$B$23&" ","")) | H6: =TRIM(IF(AND(ABS('Реестр рисков'!$G$5-0.6)<0.001,ABS('Реестр рисков'!$H$5-0.9)<0.001),'Реестр рисков'!$B$5&" ","")&IF(AND(ABS('Реестр рисков'!$G$6-0.6)<0.001,ABS('Реестр рисков'!$H$6-0.9)<0.001),'Реестр рисков'!$B$6&" ","")&IF(AND(ABS('Реестр рисков'!$G$7-0.6)<0.001,ABS('Реестр рисков'!$H$7-0.9)<0.001),'Реестр рисков'!$B$7&" ","")&IF(AND(ABS('Реестр рисков'!$G$8-0.6)<0.001,ABS('Реестр рисков'!$H$8-0.9)<0.001),'Реестр рисков'!$B$8&" ","")&IF(AND(ABS('Реестр рисков'!$G$9-0.6)<0.001,ABS('Реестр рисков'!$H$9-0.9)<0.001),'Реестр рисков'!$B$9&" ","")&IF(AND(ABS('Реестр рисков'!$G$10-0.6)<0.001,ABS('Реестр рисков'!$H$10-0.9)<0.001),'Реестр рисков'!$B$10&" ","")&IF(AND(ABS('Реестр рисков'!$G$11-0.6)<0.001,ABS('Реестр рисков'!$H$11-0.9)<0.001),'Реестр рисков'!$B$11&" ","")&IF(AND(ABS('Реестр рисков'!$G$12-0.6)<0.001,ABS('Реестр рисков'!$H$12-0.9)<0.001),'Реестр рисков'!$B$12&" ","")&IF(AND(ABS('Реестр рисков'!$G$13-0.6)<0.001,ABS('Реестр рисков'!$H$13-0.9)<0.001),'Реестр рисков'!$B$13&" ","")&IF(AND(ABS('Реестр рисков'!$G$14-0.6)<0.001,ABS('Реестр рисков'!$H$14-0.9)<0.001),'Реестр рисков'!$B$14&" ","")&IF(AND(ABS('Реестр рисков'!$G$15-0.6)<0.001,ABS('Реестр рисков'!$H$15-0.9)<0.001),'Реестр рисков'!$B$15&" ","")&IF(AND(ABS('Реестр рисков'!$G$16-0.6)<0.001,ABS('Реестр рисков'!$H$16-0.9)<0.001),'Реестр рисков'!$B$16&" ","")&IF(AND(ABS('Реестр рисков'!$G$17-0.6)<0.001,ABS('Реестр рисков'!$H$17-0.9)<0.001),'Реестр рисков'!$B$17&" ","")&IF(AND(ABS('Реестр рисков'!$G$18-0.6)<0.001,ABS('Реестр рисков'!$H$18-0.9)<0.001),'Реестр рисков'!$B$18&" ","")&IF(AND(ABS('Реестр рисков'!$G$19-0.6)<0.001,ABS('Реестр рисков'!$H$19-0.9)<0.001),'Реестр рисков'!$B$19&" ","")&IF(AND(ABS('Реестр рисков'!$G$20-0.6)<0.001,ABS('Реестр рисков'!$H$20-0.9)<0.001),'Реестр рисков'!$B$20&" ","")&IF(AND(ABS('Реестр рисков'!$G$21-0.6)<0.001,ABS('Реестр рисков'!$H$21-0.9)<0.001),'Реестр рисков'!$B$21&" ","")&IF(AND(ABS('Реестр рисков'!$G$22-0.6)<0.001,ABS('Реестр рисков'!$H$22-0.9)<0.001),'Реестр рисков'!$B$22&" ","")&IF(AND(ABS('Реестр рисков'!$G$23-0.6)<0.001,ABS('Реестр рисков'!$H$23-0.9)<0.001),'Реестр рисков'!$B$23&" ","")) -> R2 | I6: =TRIM(IF(AND(ABS('Реестр рисков'!$G$5-0.7)<0.001,ABS('Реестр рисков'!$H$5-0.9)<0.001),'Реестр рисков'!$B$5&" ","")&IF(AND(ABS('Реестр рисков'!$G$6-0.7)<0.001,ABS('Реестр рисков'!$H$6-0.9)<0.001),'Реестр рисков'!$B$6&" ","")&IF(AND(ABS('Реестр рисков'!$G$7-0.7)<0.001,ABS('Реестр рисков'!$H$7-0.9)<0.001),'Реестр рисков'!$B$7&" ","")&IF(AND(ABS('Реестр рисков'!$G$8-0.7)<0.001,ABS('Реестр рисков'!$H$8-0.9)<0.001),'Реестр рисков'!$B$8&" ","")&IF(AND(ABS('Реестр рисков'!$G$9-0.7)<0.001,ABS('Реестр рисков'!$H$9-0.9)<0.001),'Реестр рисков'!$B$9&" ","")&IF(AND(ABS('Реестр рисков'!$G$10-0.7)<0.001,ABS('Реестр рисков'!$H$10-0.9)<0.001),'Реестр рисков'!$B$10&" ","")&IF(AND(ABS('Реестр рисков'!$G$11-0.7)<0.001,ABS('Реестр рисков'!$H$11-0.9)<0.001),'Реестр рисков'!$B$11&" ","")&IF(AND(ABS('Реестр рисков'!$G$12-0.7)<0.001,ABS('Реестр рисков'!$H$12-0.9)<0.001),'Реестр рисков'!$B$12&" ","")&IF(AND(ABS('Реестр рисков'!$G$13-0.7)<0.001,ABS('Реестр рисков'!$H$13-0.9)<0.001),'Реестр рисков'!$B$13&" ","")&IF(AND(ABS('Реестр рисков'!$G$14-0.7)<0.001,ABS('Реестр рисков'!$H$14-0.9)<0.001),'Реестр рисков'!$B$14&" ","")&IF(AND(ABS('Реестр рисков'!$G$15-0.7)<0.001,ABS('Реестр рисков'!$H$15-0.9)<0.001),'Реестр рисков'!$B$15&" ","")&IF(AND(ABS('Реестр рисков'!$G$16-0.7)<0.001,ABS('Реестр рисков'!$H$16-0.9)<0.001),'Реестр рисков'!$B$16&" ","")&IF(AND(ABS('Реестр рисков'!$G$17-0.7)<0.001,ABS('Реестр рисков'!$H$17-0.9)<0.001),'Реестр рисков'!$B$17&" ","")&IF(AND(ABS('Реестр рисков'!$G$18-0.7)<0.001,ABS('Реестр рисков'!$H$18-0.9)<0.001),'Реестр рисков'!$B$18&" ","")&IF(AND(ABS('Реестр рисков'!$G$19-0.7)<0.001,ABS('Реестр рисков'!$H$19-0.9)<0.001),'Реестр рисков'!$B$19&" ","")&IF(AND(ABS('Реестр рисков'!$G$20-0.7)<0.001,ABS('Реестр рисков'!$H$20-0.9)<0.001),'Реестр рисков'!$B$20&" ","")&IF(AND(ABS('Реестр рисков'!$G$21-0.7)<0.001,ABS('Реестр рисков'!$H$21-0.9)<0.001),'Реестр рисков'!$B$21&" ","")&IF(AND(ABS('Реестр рисков'!$G$22-0.7)<0.001,ABS('Реестр рисков'!$H$22-0.9)<0.001),'Реестр рисков'!$B$22&" ","")&IF(AND(ABS('Реестр рисков'!$G$23-0.7)<0.001,ABS('Реестр рисков'!$H$23-0.9)<0.001),'Реестр рисков'!$B$23&" ","")) -> R3 | J6: =TRIM(IF(AND(ABS('Реестр рисков'!$G$5-0.8)<0.001,ABS('Реестр рисков'!$H$5-0.9)<0.001),'Реестр рисков'!$B$5&" ","")&IF(AND(ABS('Реестр рисков'!$G$6-0.8)<0.001,ABS('Реестр рисков'!$H$6-0.9)<0.001),'Реестр рисков'!$B$6&" ","")&IF(AND(ABS('Реестр рисков'!$G$7-0.8)<0.001,ABS('Реестр рисков'!$H$7-0.9)<0.001),'Реестр рисков'!$B$7&" ","")&IF(AND(ABS('Реестр рисков'!$G$8-0.8)<0.001,ABS('Реестр рисков'!$H$8-0.9)<0.001),'Реестр рисков'!$B$8&" ","")&IF(AND(ABS('Реестр рисков'!$G$9-0.8)<0.001,ABS('Реестр рисков'!$H$9-0.9)<0.001),'Реестр рисков'!$B$9&" ","")&IF(AND(ABS('Реестр рисков'!$G$10-0.8)<0.001,ABS('Реестр рисков'!$H$10-0.9)<0.001),'Реестр рисков'!$B$10&" ","")&IF(AND(ABS('Реестр рисков'!$G$11-0.8)<0.001,ABS('Реестр рисков'!$H$11-0.9)<0.001),'Реестр рисков'!$B$11&" ","")&IF(AND(ABS('Реестр рисков'!$G$12-0.8)<0.001,ABS('Реестр рисков'!$H$12-0.9)<0.001),'Реестр рисков'!$B$12&" ","")&IF(AND(ABS('Реестр рисков'!$G$13-0.8)<0.001,ABS('Реестр рисков'!$H$13-0.9)<0.001),'Реестр рисков'!$B$13&" ","")&IF(AND(ABS('Реестр рисков'!$G$14-0.8)<0.001,ABS('Реестр рисков'!$H$14-0.9)<0.001),'Реестр рисков'!$B$14&" ","")&IF(AND(ABS('Реестр рисков'!$G$15-0.8)<0.001,ABS('Реестр рисков'!$H$15-0.9)<0.001),'Реестр рисков'!$B$15&" ","")&IF(AND(ABS('Реестр рисков'!$G$16-0.8)<0.001,ABS('Реестр рисков'!$H$16-0.9)<0.001),'Реестр рисков'!$B$16&" ","")&IF(AND(ABS('Реестр рисков'!$G$17-0.8)<0.001,ABS('Реестр рисков'!$H$17-0.9)<0.001),'Реестр рисков'!$B$17&" ","")&IF(AND(ABS('Реестр рисков'!$G$18-0.8)<0.001,ABS('Реестр рисков'!$H$18-0.9)<0.001),'Реестр рисков'!$B$18&" ","")&IF(AND(ABS('Реестр рисков'!$G$19-0.8)<0.001,ABS('Реестр рисков'!$H$19-0.9)<0.001),'Реестр рисков'!$B$19&" ","")&IF(AND(ABS('Реестр рисков'!$G$20-0.8)<0.001,ABS('Реестр рисков'!$H$20-0.9)<0.001),'Реестр рисков'!$B$20&" ","")&IF(AND(ABS('Реестр рисков'!$G$21-0.8)<0.001,ABS('Реестр рисков'!$H$21-0.9)<0.001),'Реестр рисков'!$B$21&" ","")&IF(AND(ABS('Реестр рисков'!$G$22-0.8)<0.001,ABS('Реестр рисков'!$H$22-0.9)<0.001),'Реестр рисков'!$B$22&" ","")&IF(AND(ABS('Реестр рисков'!$G$23-0.8)<0.001,ABS('Реестр рисков'!$H$23-0.9)<0.001),'Реестр рисков'!$B$23&" ","")) | K6: =TRIM(IF(AND(ABS('Реестр рисков'!$G$5-0.9)<0.001,ABS('Реестр рисков'!$H$5-0.9)<0.001),'Реестр рисков'!$B$5&" ","")&IF(AND(ABS('Реестр рисков'!$G$6-0.9)<0.001,ABS('Реестр рисков'!$H$6-0.9)<0.001),'Реестр рисков'!$B$6&" ","")&IF(AND(ABS('Реестр рисков'!$G$7-0.9)<0.001,ABS('Реестр рисков'!$H$7-0.9)<0.001),'Реестр рисков'!$B$7&" ","")&IF(AND(ABS('Реестр рисков'!$G$8-0.9)<0.001,ABS('Реестр рисков'!$H$8-0.9)<0.001),'Реестр рисков'!$B$8&" ","")&IF(AND(ABS('Реестр рисков'!$G$9-0.9)<0.001,ABS('Реестр рисков'!$H$9-0.9)<0.001),'Реестр рисков'!$B$9&" ","")&IF(AND(ABS('Реестр рисков'!$G$10-0.9)<0.001,ABS('Реестр рисков'!$H$10-0.9)<0.001),'Реестр рисков'!$B$10&" ","")&IF(AND(ABS('Реестр рисков'!$G$11-0.9)<0.001,ABS('Реестр рисков'!$H$11-0.9)<0.001),'Реестр рисков'!$B$11&" ","")&IF(AND(ABS('Реестр рисков'!$G$12-0.9)<0.001,ABS('Реестр рисков'!$H$12-0.9)<0.001),'Реестр рисков'!$B$12&" ","")&IF(AND(ABS('Реестр рисков'!$G$13-0.9)<0.001,ABS('Реестр рисков'!$H$13-0.9)<0.001),'Реестр рисков'!$B$13&" ","")&IF(AND(ABS('Реестр рисков'!$G$14-0.9)<0.001,ABS('Реестр рисков'!$H$14-0.9)<0.001),'Реестр рисков'!$B$14&" ","")&IF(AND(ABS('Реестр рисков'!$G$15-0.9)<0.001,ABS('Реестр рисков'!$H$15-0.9)<0.001),'Реестр рисков'!$B$15&" ","")&IF(AND(ABS('Реестр рисков'!$G$16-0.9)<0.001,ABS('Реестр рисков'!$H$16-0.9)<0.001),'Реестр рисков'!$B$16&" ","")&IF(AND(ABS('Реестр рисков'!$G$17-0.9)<0.001,ABS('Реестр рисков'!$H$17-0.9)<0.001),'Реестр рисков'!$B$17&" ","")&IF(AND(ABS('Реестр рисков'!$G$18-0.9)<0.001,ABS('Реестр рисков'!$H$18-0.9)<0.001),'Реестр рисков'!$B$18&" ","")&IF(AND(ABS('Реестр рисков'!$G$19-0.9)<0.001,ABS('Реестр рисков'!$H$19-0.9)<0.001),'Реестр рисков'!$B$19&" ","")&IF(AND(ABS('Реестр рисков'!$G$20-0.9)<0.001,ABS('Реестр рисков'!$H$20-0.9)<0.001),'Реестр рисков'!$B$20&" ","")&IF(AND(ABS('Реестр рисков'!$G$21-0.9)<0.001,ABS('Реестр рисков'!$H$21-0.9)<0.001),'Реестр рисков'!$B$21&" ","")&IF(AND(ABS('Реестр рисков'!$G$22-0.9)<0.001,ABS('Реестр рисков'!$H$22-0.9)<0.001),'Реестр рисков'!$B$22&" ","")&IF(AND(ABS('Реестр рисков'!$G$23-0.9)<0.001,ABS('Реестр рисков'!$H$23-0.9)<0.001),'Реестр рисков'!$B$23&" ","")) | L6: =TRIM(IF(AND(ABS('Реестр рисков'!$G$5-1)<0.001,ABS('Реестр рисков'!$H$5-0.9)<0.001),'Реестр рисков'!$B$5&" ","")&IF(AND(ABS('Реестр рисков'!$G$6-1)<0.001,ABS('Реестр рисков'!$H$6-0.9)<0.001),'Реестр рисков'!$B$6&" ","")&IF(AND(ABS('Реестр рисков'!$G$7-1)<0.001,ABS('Реестр рисков'!$H$7-0.9)<0.001),'Реестр рисков'!$B$7&" ","")&IF(AND(ABS('Реестр рисков'!$G$8-1)<0.001,ABS('Реестр рисков'!$H$8-0.9)<0.001),'Реестр рисков'!$B$8&" ","")&IF(AND(ABS('Реестр рисков'!$G$9-1)<0.001,ABS('Реестр рисков'!$H$9-0.9)<0.001),'Реестр рисков'!$B$9&" ","")&IF(AND(ABS('Реестр рисков'!$G$10-1)<0.001,ABS('Реестр рисков'!$H$10-0.9)<0.001),'Реестр рисков'!$B$10&" ","")&IF(AND(ABS('Реестр рисков'!$G$11-1)<0.001,ABS('Реестр рисков'!$H$11-0.9)<0.001),'Реестр рисков'!$B$11&" ","")&IF(AND(ABS('Реестр рисков'!$G$12-1)<0.001,ABS('Реестр рисков'!$H$12-0.9)<0.001),'Реестр рисков'!$B$12&" ","")&IF(AND(ABS('Реестр рисков'!$G$13-1)<0.001,ABS('Реестр рисков'!$H$13-0.9)<0.001),'Реестр рисков'!$B$13&" ","")&IF(AND(ABS('Реестр рисков'!$G$14-1)<0.001,ABS('Реестр рисков'!$H$14-0.9)<0.001),'Реестр рисков'!$B$14&" ","")&IF(AND(ABS('Реестр рисков'!$G$15-1)<0.001,ABS('Реестр рисков'!$H$15-0.9)<0.001),'Реестр рисков'!$B$15&" ","")&IF(AND(ABS('Реестр рисков'!$G$16-1)<0.001,ABS('Реестр рисков'!$H$16-0.9)<0.001),'Реестр рисков'!$B$16&" ","")&IF(AND(ABS('Реестр рисков'!$G$17-1)<0.001,ABS('Реестр рисков'!$H$17-0.9)<0.001),'Реестр рисков'!$B$17&" ","")&IF(AND(ABS('Реестр рисков'!$G$18-1)<0.001,ABS('Реестр рисков'!$H$18-0.9)<0.001),'Реестр рисков'!$B$18&" ","")&IF(AND(ABS('Реестр рисков'!$G$19-1)<0.001,ABS('Реестр рисков'!$H$19-0.9)<0.001),'Реестр рисков'!$B$19&" ","")&IF(AND(ABS('Реестр рисков'!$G$20-1)<0.001,ABS('Реестр рисков'!$H$20-0.9)<0.001),'Реестр рисков'!$B$20&" ","")&IF(AND(ABS('Реестр рисков'!$G$21-1)<0.001,ABS('Реестр рисков'!$H$21-0.9)<0.001),'Реестр рисков'!$B$21&" ","")&IF(AND(ABS('Реестр рисков'!$G$22-1)<0.001,ABS('Реестр рисков'!$H$22-0.9)<0.001),'Реестр рисков'!$B$22&" ","")&IF(AND(ABS('Реестр рисков'!$G$23-1)<0.001,ABS('Реестр рисков'!$H$23-0.9)<0.001),'Реестр рисков'!$B$23&" ",""))
